Workbook

Sheet Summary
A1: TAKAPLAST — SUMMARY
A3: FUNDING REQUIREMENT
A4: Total CAPEX (incl. 10% contingency) | B4: =CAPEX_Consolidated!B17 -> 6179129.6
A5: Working Capital (24 months) | B5: =CAPEX_Consolidated!B19 -> 2360476.9 | C5: Pre-revenue buffer
A6: TOTAL FUNDING NEED | B6: =CAPEX_Consolidated!B20 -> 8539606.5 | C6: 100% investor-funded
A8: KEY METRICS
A9: Target capacity | B9: 50 t/d net (18,250 t/yr) | C9: Nominal by M24
A10: Revenue streams | B10: 3 flux + complementary | C10: Pellets + BTP + LPG + carbon credits + export
A11: 3-flux operational start date | B11: M8 | C11: 17-day installation after container M7
A12: Monthly EBITDA breakeven | B12: M12 | C12: 48% capacity
A13: CAPEX payback | B13: 18-22 months | C13: Cumulative net cash
A14: Direct + indirect jobs | B14: ~115 direct + 50 coop collectors
A15: CO2 avoided | B15: 55,080 tCO2eq/yr (Year 5) | C15: ≡ 12,000 cars
A17: 5-YEAR FINANCIAL PROJECTIONS
A18: Revenue Year 1 (core) | B18: =Revenue!E6 -> 1800000
A19: Revenue Year 2 (core) | B19: =Revenue!F6 -> 9480000
A20: Revenue Year 3 (core) | B20: =Revenue!G6 -> 11640000 | C20: Steady state
A21: Revenue Year 4 (core) | B21: =Revenue!H6 -> 12000000
A22: Revenue Year 5 (core) | B22: =Revenue!I6 -> 12000000
A24: OPEX Year 1 | B24: =OPEX_Operations!D53 -> 1837139
A25: OPEX Year 2 | B25: =OPEX_Operations!E53 -> 3365468.6
A26: OPEX Year 3 | B26: =OPEX_Operations!F53 -> 4046531.8
A27: OPEX Year 4 | B27: =OPEX_Operations!G53 -> 4098000
A28: OPEX Year 5 | B28: =OPEX_Operations!H53 -> 4118000
A30: EBITDA Year 1 (core) | B30: =Revenue!E21 -> -37139
A31: EBITDA Year 2 (core) | B31: =Revenue!F21 -> 6114531.4
A32: EBITDA Year 3 (core) | B32: =Revenue!G21 -> 7593468.2 | C32: Steady state
A33: EBITDA Year 4 (core) | B33: =Revenue!H21 -> 7902000
A34: EBITDA Year 5 (core) | B34: =Revenue!I21 -> 7882000
A35: ROI 5 years (post-tax 30%) | B35: >400%
A37: COMPLEMENTARY REVENUE (Yr5 with carbon credits at full scale)
A38: Complementary Year 1 | B38: =Revenue!E14 -> 0
A39: Complementary Year 2 | B39: =Revenue!F14 -> 197500
A40: Complementary Year 3 | B40: =Revenue!G14 -> 663250
A41: Complementary Year 4 | B41: =Revenue!H14 -> 2031750
A42: Complementary Year 5 | B42: =Revenue!I14 -> 3344994
A44: Total Revenue Year 1 (core + compl.) | B44: =Revenue!E16 -> 1800000
A45: Total Revenue Year 2 (core + compl.) | B45: =Revenue!F16 -> 9677500
A46: Total Revenue Year 3 (core + compl.) | B46: =Revenue!G16 -> 12303250
A47: Total Revenue Year 4 (core + compl.) | B47: =Revenue!H16 -> 14031750
...

Sheet Assumptions
A1: Parameter | B1: Value | C1: Unit | D1: Notes
A2: TARGET CAPACITY
A3: Net processing capacity | B3: 50 | C3: t/day | D3: Nominal by M24
A4: Operating days per year | B4: 365 | C4: days
A5: Annual capacity | B5: =B3*B4 -> 18250 | C5: t/year | D5: 50×365 = 18,250
A6: Import coefficient | B6: 1.44 | C6: × | D6: Customs 10% + VAT 16% + logistics
A7: PLASTIC PROCUREMENT
A8: Purchase price per kg | B8: 0.03 | C8: $/kg | D8: Mix: informal $0.02, coops $0.04, industry $0.06
A9: Purchase price per ton | B9: =B8*1000 -> 30 | C9: $/t
A10: Annual plastic cost (100%) | B10: =B5*B9 -> 547500 | C10: $/year | D10: 18,250t × $30/t
A11: ELECTRICITY
A12: Plant consumption | B12: 115000 | C12: kWh/month | D12: All machines+lighting+HVAC+pumps
A13: SNEL grid share | B13: 0.7 | C13: ratio | D13: 70% SNEL / 30% diesel backup
A14: SNEL rate | B14: 0.18 | C14: $/kWh | D14: Current DRC tariff
A15: Diesel generator rate | B15: 0.35 | C15: $/kWh | D15: Including fuel cost
A16: Annual electricity cost | B16: =B12*12*(B13*B14+(1-B13)*B15) -> 318780 | C16: $/year
A17: WATER
A18: Daily water consumption | B18: 200 | C18: m³/day | D18: Washing + cooling + sanitary
A19: Water cost per m³ | B19: 2 | C19: $/m³ | D19: Borehole+treatment
A20: Annual water cost | B20: =B18*B19*B4 -> 146000 | C20: $/year | D20: 200×$2×365
A21: FUEL — VEHICLES
A22: Compactor trucks | B22: 5 | C22: units | D22: 10t compactors
A23: Monthly fuel per truck | B23: 200 | C23: L/month
A24: Executive/management vehicles | B24: 9 | C24: vehicles | D24: CEO+DG+CTO+COO+CCO+CMO+CFO = 7 SUVs + 2 utility
A25: Monthly fuel per vehicle | B25: 150 | C25: L/month
A26: Diesel price | B26: 1.3 | C26: $/L | D26: Kinshasa pump price
A27: Annual truck fuel | B27: =B22*B23*B26*12 -> 15600 | C27: $/year
A28: Annual vehicle fuel | B28: =B24*B25*B26*12 -> 21060 | C28: $/year
A29: CAPACITY RAMP (drives Revenue & variable OPEX)
A30: Year 1 utilization | B30: 0.15 | C30: ratio | D30: M1-7 collection only + M8-12 ramp 15-48% → ~15% avg
A31: Year 2 utilization | B31: 0.79 | C31: ratio | D31: 52-95% → ~79% avg
A32: Year 3 utilization | B32: 0.97 | C32: ratio | D32: 95-100%
A33: Year 4 utilization | B33: 1 | C33: ratio | D33: Full capacity
A34: Year 5 utilization | B34: 1 | C34: ratio | D34: Full capacity + potential expansion
A35: KEY FINANCIAL
A36: Contingency rate | B36: 0.1 | C36: ratio | D36: Min 10% of CAPEX
A37: CNSS employer rate | B37: 0.25 | C37: ratio | D37: DRC social security
A38: Corporate tax rate | B38: 0.3 | C38: ratio | D38: DRC standard
A39: REVENUE ASSUMPTIONS — CORE (at 100% capacity)
A40: Pellets revenue (100%) | B40: 7200000 | C40: $/year | D40: 11,077t × $650/t
...

Sheet CAPEX_Consolidated
A1: CAPEX Category | B1: Amount (USD) | C1: % of CAPEX | D1: Source | E1: Key Assumptions
A2: Production equipment — 3 flux (delivered KIN) | B2: =CAPEX_Equipment!I42 -> 2119600 | C2: =B2/B17 -> 0.34302566 | D2: Quotes | E2: ×1.44 import, 40' container
A3: Land — Kinkole 8,000m² (purchase+frees) | B3: =CAPEX_Infra_Vehicles_IT!F6 -> 218000 | C3: =B3/B17 -> 0.03528005 | D3: Estimate
A4: Construction — hall+offices+annexes | B4: =CAPEX_Infra_Vehicles_IT!F17 -> 570000 | C4: =B4/B17 -> 0.092246002 | D4: Estimate
A5: Power & electrical | B5: =CAPEX_Infra_Vehicles_IT!F26 -> 275000 | C5: =B5/B17 -> 0.04450465 | D5: Estimate
A6: Water+pumps+effluent | B6: =CAPEX_Infra_Vehicles_IT!F33 -> 73000 | C6: =B6/B17 -> 0.011813962 | D6: Estimate
A7: HVAC | B7: =CAPEX_Infra_Vehicles_IT!F38 -> 27000 | C7: =B7/B17 -> 0.0043695475 | D7: Estimate
A8: Security | B8: =CAPEX_Infra_Vehicles_IT!F43 -> 24000 | C8: =B8/B17 -> 0.0038840422 | D8: Estimate
A9: Vehicles (5 trucks+7 SUVs+2 utility) | B9: =CAPEX_Infra_Vehicles_IT!F54 -> 1785000 | C9: =B9/B17 -> 0.28887564 | D9: Estimate
A10: IT & traceability | B10: =CAPEX_Infra_Vehicles_IT!F60 -> 115000 | C10: =B10/B17 -> 0.018611035 | D10: Estimate
A11: Legal & certifications | B11: =CAPEX_Infra_Vehicles_IT!F71 -> 91000 | C11: =B11/B17 -> 0.014726993 | D11: Estimate
A12: Training & tech assistance | B12: =CAPEX_Infra_Vehicles_IT!F76 -> 85000 | C12: =B12/B17 -> 0.013755983 | D12: Estimate
A13: Technical AMO & Industrial Integration | B13: =(B4+B2)*Assumptions!B52 -> 134480 | C13: =B13/B17 -> 0.021763583 | D13: Estimate
A14: Subtotal CAPEX (excl. contingency) | B14: =SUM(B2:B13) -> 5517080
A15: Contingency (10%) | B15: =B14*Assumptions!B36 -> 551708 | D15: Calculated | E15: Min 10% — delays, FX, unforeseen
A16: Customs / FX unforeseen buffer | B16: =2%*B14 -> 110341.6 | E16: Estimate 2% – customs delays, extra storage, FX slippage
A17: TOTAL CAPEX | B17: =B14+B15+B16 -> 6179129.6
A19: Working Capital — 24 months | B19: =Working_Capital!G35 -> 2360476.9 | D19: WC tab | E19: Pre-revenue buffer M1-M24
A20: TOTAL FUNDING REQUIREMENT | B20: =B17+B19 -> 8539606.5 | E20: CAPEX + Working Capital

Sheet CAPEX_Equipment
A1: Flux | B1: Equipment | C1: Supplier | D1: Country | E1: Qty | F1: FOB ($) | G1: FOB Tot ($) | H1: Coeff. | I1: Delivered ($) | J1: Notes
A2: FLUX 1 — HDPE/PP PELLETS
A3: Pellets | B3: Automated NIR sorter | C3: Wanrooe Machinery | D3: China | E3: 1 | F3: 10000 | G3: =E3*F3 -> 10000 | H3: =Assumptions!B6 -> 1.44 | I3: =G3*H3 -> 14400 | J3: HDPE/PP/mix, 2 t/h
A4: Pellets | B4: Plastic washer (500kg/h) | C4: Genius Machinery | D4: China | E4: 3 | F4: 35000 | G4: =E4*F4 -> 105000 | H4: =Assumptions!B6 -> 1.44 | I4: =G4*H4 -> 151200 | J4: 3 parallel lines
A5: Pellets | B5: Plastic shredder | C5: Genius Machinery | D5: China | E5: 4 | F5: 35000 | G5: =E5*F5 -> 140000 | H5: =Assumptions!B6 -> 1.44 | I5: =G5*H5 -> 201600 | J5: 30 t/d sorted combined
A6: Pellets | B6: Centrifugal dryer (8t/d) | C6: Zhangjiagang Lianding | D6: China | E6: 5 | F6: 15000 | G6: =E6*F6 -> 75000 | H6: =Assumptions!B6 -> 1.44 | I6: =G6*H6 -> 108000 | J6: 1 per extruder
A7: Pellets | B7: Extruder pelletizer (200kg/h) | C7: Nanjing Haisi | D7: China | E7: 5 | F7: 45000 | G7: =E7*F7 -> 225000 | H7: =Assumptions!B6 -> 1.44 | I7: =G7*H7 -> 324000 | J7: Bottleneck #1: 5×8t/d=40t/d
A8: Pellets | B8: Pelletizing cooler | C8: Tongsan Plastic | D8: China | E8: 5 | F8: 25000 | G8: =E8*F8 -> 125000 | H8: =Assumptions!B6 -> 1.44 | I8: =G8*H8 -> 180000 | J8: 1:1 with extruders
A9: Pellets | B9: Water filtration (5m³/h) | C9: Local/import | D9: DRC | E9: 1 | F9: 10000 | G9: =E9*F9 -> 10000 | H9: 1 | I9: =G9*H9 -> 10000 | J9: No import
B10: Subtotal FLUX 1 | G10: =SUM(G3:G9) -> 690000 | I10: =SUM(I3:I9) -> 989200
A11: FLUX 2 — ENERGY (LPG/SYNGAS)
A12: Energy | B12: Fine shredder (300kg/h) | C12: Zhangjiagang Sevenstars | D12: China | E12: 1 | F12: 20000 | G12: =E12*F12 -> 20000 | H12: =Assumptions!B6 -> 1.44 | I12: =G12*H12 -> 28800 | J12: Gasification prep
A13: Energy | B13: Rotary dryer (500kg/h) | C13: Henan Hongji | D13: China | E13: 1 | F13: 25000 | G13: =E13*F13 -> 25000 | H13: =Assumptions!B6 -> 1.44 | I13: =G13*H13 -> 36000
A14: Energy | B14: Gasifier 700°C (10t/d) | C14: Ankur Scientific | D14: India | E14: 2 | F14: 80000 | G14: =E14*F14 -> 160000 | H14: =Assumptions!B6 -> 1.44 | I14: =G14*H14 -> 230400 | J14: 150+ Africa installations
A15: Energy | B15: Gas filtration (100Nm³/h) | C15: EnviroPro | D15: France | E15: 1 | F15: 30000 | G15: =E15*F15 -> 30000 | H15: =Assumptions!B6 -> 1.44 | I15: =G15*H15 -> 43200
A16: Energy | B16: LPG compressor (50bar) | C16: Atlas Copco | D16: Sweden | E16: 2 | F16: 15000 | G16: =E16*F16 -> 30000 | H16: =Assumptions!B6 -> 1.44 | I16: =G16*H16 -> 43200
A17: Energy | B17: LPG storage cylinders | C17: Local supplier | D17: DRC | E17: 50 | F17: 400 | G17: =E17*F17 -> 20000 | H17: 1 | I17: =G17*H17 -> 20000
A18: Energy | B18: LPG safety system | C18: Import | D18: Europe | E18: 1 | F18: 15000 | G18: =E18*F18 -> 15000 | H18: =Assumptions!B6 -> 1.44 | I18: =G18*H18 -> 21600 | J18: Detectors, valves
B19: Subtotal FLUX 2 | G19: =SUM(G12:G18) -> 300000 | I19: =SUM(I12:I18) -> 423200
A20: FLUX 3 — CONSTRUCTION (PAVERS/COMPOSITES)
A21: BTP | B21: Heavy shredder (800kg/h) | C21: Changshu Shouyu | D21: China | E21: 1 | F21: 15000 | G21: =E21*F21 -> 15000 | H21: =Assumptions!B6 -> 1.44 | I21: =G21*H21 -> 21600
A22: BTP | B22: Heated bitumen mixer (2t) | C22: Liaoyang Honji | D22: China | E22: 1 | F22: 35000 | G22: =E22*F22 -> 35000 | H22: =Assumptions!B6 -> 1.44 | I22: =G22*H22 -> 50400
A23: BTP | B23: Hydraulic press 100t/700bar | C23: Zhengzhou Alliance | D23: China | E23: 3 | F23: 40000 | G23: =E23*F23 -> 120000 | H23: =Assumptions!B6 -> 1.44 | I23: =G23*H23 -> 172800 | J23: Bottleneck #2
A24: BTP | B24: Paver/tile molds | C24: Local fabrication | D24: DRC | E24: 30 | F24: 500 | G24: =E24*F24 -> 15000 | H24: 1 | I24: =G24*H24 -> 15000 | J24: Various formats
A25: BTP | B25: Bitumen heating 5000L | C25: Local/import | D25: DRC | E25: 1 | F25: 20000 | G25: =E25*F25 -> 20000 | H25: 1 | I25: =G25*H25 -> 20000
A26: BTP | B26: Cooling conveyor | C26: Import | D26: China | E26: 1 | F26: 12000 | G26: =E26*F26 -> 12000 | H26: =Assumptions!B6 -> 1.44 | I26: =G26*H26 -> 17280 | J26: Post-pressing
A27: BTP | B27: Cutting/finishing table | C27: Local | D27: DRC | E27: 2 | F27: 5000 | G27: =E27*F27 -> 10000 | H27: 1 | I27: =G27*H27 -> 10000
B28: Subtotal FLUX 3 | G28: =SUM(G21:G27) -> 227000 | I28: =SUM(I21:I27) -> 307080
A29: SHARED EQUIPMENT
A30: Shared | B30: Overhead Crane/forklift | C30: Import | D30: China | E30: 1 | F30: 18000 | G30: =E30*F30 -> 18000 | H30: =Assumptions!B6 -> 1.44 | I30: =G30*H30 -> 25920
A31: Shared | B31: Air compressor | C31: Atlas Copco | D31: Sweden | E31: 1 | F31: 8000 | G31: =E31*F31 -> 8000 | H31: =Assumptions!B6 -> 1.44 | I31: =G31*H31 -> 11520 | J31: Pneumatic tools
A32: Shared | B32: Industrial scales | C32: Local | D32: DRC | E32: 3 | F32: 2000 | G32: =E32*F32 -> 6000 | H32: 1 | I32: =G32*H32 -> 6000 | J32: In + prod + out
A33: Shared | B33: Quality Lab equipment | C33: Import | D33: Europe | E33: 1 | F33: 9000 | G33: =E33*F33 -> 9000 | H33: =Assumptions!B6 -> 1.44 | I33: =G33*H33 -> 12960 | J33: MFI, density, tensile
A34: Shared | B34: Maintenance tooling | C34: Various | D34: China | E34: 1 | F34: 5000 | G34: =E34*F34 -> 5000 | H34: =Assumptions!B6 -> 1.44 | I34: =G34*H34 -> 7200
A35: Shared | B35: Critical spares stock | C35: Suppliers | D35: Various | E35: 1 | F35: 8000 | G35: =E35*F35 -> 8000 | H35: =Assumptions!B6 -> 1.44 | I35: =G35*H35 -> 11520 | J35: Preventive stock
A36: Shared | B36: Freight+customs+insurance | C36: DHL GF | D36: Intl | E36: 1 | F36: 150000 | G36: =E36*F36 -> 150000 | H36: 1 | I36: =G36*H36 -> 150000 | J36: 40' container to KIN
A37: Shared | B37: Installation+commissioning | C37: On-site | D37: DRC | E37: 1 | F37: 100000 | G37: =E37*F37 -> 100000 | H37: 1 | I37: =G37*H37 -> 100000 | J37: Supervision + labor
A38: Shared | B38: Accessories/connectors/misc | C38: Various | D38: Various | E38: 1 | F38: 75000 | G38: =E38*F38 -> 75000 | H38: 1 | I38: =G38*H38 -> 75000 | J38: Completion items
B39: Subtotal SHARED EQUIPMENT | G39: =SUM(G30:G38) -> 379000 | I39: =SUM(I30:I38) -> 400120
B41: TOTAL EQUIPMENT FOB | G41: =G10+G19+G28+G39 -> 1596000
...

Sheet CAPEX_Infra_Vehicles_IT
A1: Cat. | B1: Item | C1: Spec | D1: Qty | E1: Unit ($) | F1: Total ($) | G1: Phase | H1: Notes
A2: LAND — Kinkole 8,000 m²
A3: Land | B3: Land acquisition 8,000m² | C3: Kinkole | D3: 1 | E3: 200000 | F3: =D3*E3 -> 200000 | G3: M1-M2 | H3: $25/m²
A4: Land | B4: Notary / transfer fees | D4: 1 | E4: 15000 | F4: =D4*E4 -> 15000 | G4: M1-M2 | H4: ~7.5%
A5: Land | B5: Survey+boundary (topographic) | D5: 1 | E5: 3000 | F5: =D5*E5 -> 3000 | G5: M1
B6: Subtotal LAND | F6: =SUM(F3:F5) -> 218000
A7: CONSTRUCTION
A8: C | B8: Industrial hall 3,000m² | C8: Steel+roof+slab | D8: 1 | E8: 350000 | F8: =D8*E8 -> 350000 | G8: M2-M6 | H8: $115/m²
A9: C | B9: Offices 300m² | C9: Masonry | D9: 1 | E9: 60000 | F9: =D9*E9 -> 60000 | G9: M3-M6 | H9: $200/m²
A10: C | B10: Locker rooms 100m² | D10: 1 | E10: 20000 | F10: =D10*E10 -> 20000 | G10: M3-M5
A11: C | B11: Quality lab 50m² | C11: A/C | D11: 1 | E11: 15000 | F11: =D11*E11 -> 15000 | G11: M4-M6
A12: C | B12: Raw storage 500m² | C12: Open-sided | D12: 1 | E12: 25000 | F12: =D12*E12 -> 25000 | G12: M3-M5 | H12: $50/m²
A13: C | B13: Finished storage 400m² | C13: Enclosed | D13: 1 | E13: 30000 | F13: =D13*E13 -> 30000 | G13: M3-M5 | H13: $75/m²
A14: C | B14: Internal roads 1,500m² | C14: Concrete | D14: 1 | E14: 30000 | F14: =D14*E14 -> 30000 | G14: M3-M6 | H14: $20/m²
A15: C | B15: Perimeter fence 360lm | C15: Wall+mesh | D15: 1 | E15: 25000 | F15: =D15*E15 -> 25000 | G15: M2-M3 | H15: $70/lm
A16: C | B16: Drainage | D16: 1 | E16: 15000 | F16: =D16*E16 -> 15000 | G16: M3-M5
B17: Subtotal CONSTRUCTION | F17: =SUM(F8:F16) -> 570000
A18: POWER
A19: P | B19: Generator 200kVA #1 | C19: Incl.install | D19: 1 | E19: 65000 | F19: =D19*E19 -> 65000 | G19: M2-M4 | H19: Primary
A20: P | B20: Generator 200kVA #2 | C20: Incl.install | D20: 1 | E20: 65000 | F20: =D20*E20 -> 65000 | G20: M2-M4 | H20: Redundancy
A21: P | B21: SNEL+transfo 400kVA | D21: 1 | E21: 25000 | F21: =D21*E21 -> 25000 | G21: M2-M4 | H21: Grid stabilization
A22: P | B22: TGBT+distribution | D22: 1 | E22: 18000 | F22: =D22*E22 -> 18000 | G22: M4-M6 | H22: 380V 3-phase
A23: P | B23: Solar 150kWp | C23: Panels+inv+batt | D23: 1 | E23: 85000 | F23: =D23*E23 -> 85000 | G23: Yr2 | H23: ROI 1.2 yr
A24: P | B24: Diesel tank 5,000L | D24: 1 | E24: 5000 | F24: =D24*E24 -> 5000 | G24: M3
A25: P | B25: Gen. maint. Yr1 | D25: 1 | E25: 12000 | F25: =D25*E25 -> 12000 | G25: Yr1 | H25: Preventive
B26: Subtotal POWER | F26: =SUM(F19:F25) -> 275000
A27: WATER
A28: W | B28: Industrial Borehole | C28: ~50m | D28: 1 | E28: 15000 | F28: =D28*E28 -> 15000 | G28: M2-M4
A29: W | B29: Water Pumps 2gal/min 17h/d | C29: 25 units (centrifugal+piping) | D29: 25 | E29: 800 | F29: =D29*E29 -> 20000 | G29: M3-M5 | H29: 25×7.7m³/d=192m³/d
A30: W | B30: Storage Tank 50m³ | C30: Buffer | D30: 1 | E30: 8000 | F30: =D30*E30 -> 8000 | G30: M3-M5 | H30: 4h buffer
A31: W | B31: Distribution network | C31: PVC+valves | D31: 1 | E31: 10000 | F31: =D31*E31 -> 10000 | G31: M4-M6
A32: W | B32: Wastewater treatment | C32: Setting+filtration | D32: 1 | E32: 20000 | F32: =D32*E32 -> 20000 | G32: M4-M6 | H32: MECNT compliance
B33: Subtotal WATER | F33: =SUM(F28:F32) -> 73000
A34: HVAC
A35: H | B35: Office splits | C35: 12-18kBTU | D35: 6 | E35: 2500 | F35: =D35*E35 -> 15000 | G35: M5-M6
A36: H | B36: Lab splits | C36: 18kBTU | D36: 2 | E36: 3000 | F36: =D36*E36 -> 6000 | G36: M5-M6 | H36: Temp. control
A37: H | B37: Industrial ventilation | C37: Axial | D37: 4 | E37: 1500 | F37: =D37*E37 -> 6000 | G37: M5-M6 | H37: Heat/fume exhaust
B38: Subtotal HVAC | F38: =SUM(F35:F37) -> 27000
A39: SECURITY
A40: S | B40: CCTV 24/7 | C40: 8 IP+NVR | D40: 1 | E40: 8000 | F40: =D40*E40 -> 8000 | G40: M3
...

Sheet OPEX_HR
A1: Cat. | B1: Position | C1: # | D1: Monthly ($) | E1: Annual ($) | F1: CNSS 25% | G1: Benefits* | H1: Bonuses** | I1: Total/yr ($) | J1: Car? | K1: Start | L1: Link
A2: EXECUTIVE TEAM
A3: Exec | B3: CEO / Founder (Président) | C3: 1 | D3: 20000 | E3: =C3*D3*12 -> 240000 | F3: =E3*Assumptions!B37 -> 60000 | G3: =E3*0.05 -> 12000 | H3: =E3*0.1 -> 24000 | I3: =E3+F3+G3+H3 -> 336000 | J3: Yes | K3: M0 — strategic vision, investors, expansion | L3: www.linkedin.com/in/joeloxybel
A4: Exec | B4: Managing Director / Gérant statutaire | C4: 1 | D4: 8000 | E4: =C4*D4*12 -> 96000 | F4: =E4*Assumptions!B37 -> 24000 | G4: =E4*0.05 -> 4800 | H4: =E4*0.1 -> 9600 | I4: =E4+F4+G4+H4 -> 134400 | J4: Yes | K4: M12 — daily operations, legal representative | L4: https://www.linkedin.com/in/patrick-kahasha-mbasha-1a177323/
A5: Exec | B5: Chief Technology Officer (CTO) | C5: 1 | D5: 7000 | E5: =C5*D5*12 -> 84000 | F5: =E5*Assumptions!B37 -> 21000 | G5: =E5*0.05 -> 4200 | H5: =E5*0.1 -> 8400 | I5: =E5+F5+G5+H5 -> 117600 | J5: Yes | K5: M1 — critical, plant engineering | L5: https://www.linkedin.com/in/jiry-ngoma-b4872a143/
A6: Exec | B6: Chief Operating Officer (COO) | C6: 1 | D6: 5000 | E6: =C6*D6*12 -> 60000 | F6: =E6*Assumptions!B37 -> 15000 | G6: =E6*0.05 -> 3000 | H6: =E6*0.5 -> 30000 | I6: =E6+F6+G6+H6 -> 108000 | J6: Yes | K6: M1 — supply chain, logistics | L6: https://www.linkedin.com/in/serge-tshishimbi-2b3396140/
A7: Exec | B7: Chief Commercial Officer (CCO) | C7: 1 | D7: 4000 | E7: =C7*D7*12 -> 48000 | F7: =E7*Assumptions!B37 -> 12000 | G7: =E7*0.05 -> 2400 | H7: =E7*1 -> 48000 | I7: =E7+F7+G7+H7 -> 110400 | J7: Yes | K7: M8 — sales 3 flux + export | L7: https://www.linkedin.com/in/serge-bazola-ndelo-59551941/
A8: Exec | B8: Chief Marketing Officer (CMO) | C8: 1 | D8: 4000 | E8: =C8*D8*12 -> 48000 | F8: =E8*Assumptions!B37 -> 12000 | G8: =E8*0.05 -> 2400 | H8: =E8*0.1 -> 4800 | I8: =E8+F8+G8+H8 -> 67200 | J8: Yes | K8: M4 — brand, positioning, market penetration | L8: https://www.linkedin.com/in/aurorejoncour/
A9: Exec | B9: Chief Financial Officer (CFO) | C9: 1 | D9: 5000 | E9: =C9*D9*12 -> 60000 | F9: =E9*Assumptions!B37 -> 15000 | G9: =E9*0.05 -> 3000 | H9: =E9*0.1 -> 6000 | I9: =E9+F9+G9+H9 -> 84000 | J9: Yes | K9: M3 — OHADA accounting, BAD/AFD reporting
B10: Subtotal | C10: =SUM(C3:C9) -> 7 | I10: =SUM(I3:I9) -> 957600
A11: MIDDLE MANAGEMENT
A12: Mgmt | B12: Collection & Logistics Manager | C12: 1 | D12: 3500 | E12: =C12*D12*12 -> 42000 | F12: =E12*Assumptions!B37 -> 10500 | G12: =E12*0.05 -> 2100 | H12: =E12*0.1 -> 4200 | I12: =E12+F12+G12+H12 -> 58800 | J12: No | K12: M2
A13: Mgmt | B13: Production Manager | C13: 1 | D13: 3000 | E13: =C13*D13*12 -> 36000 | F13: =E13*Assumptions!B37 -> 9000 | G13: =E13*0.05 -> 1800 | H13: =E13*0.1 -> 3600 | I13: =E13+F13+G13+H13 -> 50400 | J13: No | K13: M6
A14: Mgmt | B14: Accountant | C14: 1 | D14: 3500 | E14: =C14*D14*12 -> 42000 | F14: =E14*Assumptions!B37 -> 10500 | G14: =E14*0.05 -> 2100 | H14: =E14*0.1 -> 4200 | I14: =E14+F14+G14+H14 -> 58800 | J14: No | K14: M2
A15: Mgmt | B15: HR / Admin Manager | C15: 1 | D15: 3000 | E15: =C15*D15*12 -> 36000 | F15: =E15*Assumptions!B37 -> 9000 | G15: =E15*0.05 -> 1800 | H15: =E15*0.1 -> 3600 | I15: =E15+F15+G15+H15 -> 50400 | J15: No | K15: M4
A16: Mgmt | B16: Maintenance Engineer | C16: 1 | D16: 2500 | E16: =C16*D16*12 -> 30000 | F16: =E16*Assumptions!B37 -> 7500 | G16: =E16*0.05 -> 1500 | H16: =E16*0.1 -> 3000 | I16: =E16+F16+G16+H16 -> 42000 | J16: No | K16: M6
A17: Mgmt | B17: Quality Manager | C17: 1 | D17: 2500 | E17: =C17*D17*12 -> 30000 | F17: =E17*Assumptions!B37 -> 7500 | G17: =E17*0.05 -> 1500 | H17: =E17*0.1 -> 3000 | I17: =E17+F17+G17+H17 -> 42000 | J17: No | K17: M8
B18: Subtotal | C18: =SUM(C12:C17) -> 6 | I18: =SUM(I12:I17) -> 302400
A19: IT & TRACEABILITY
A20: IT | B20: IT / Traceability Project Mgr | C20: 1 | D20: 3500 | E20: =C20*D20*12 -> 42000 | F20: =E20*Assumptions!B37 -> 10500 | G20: =E20*0.05 -> 2100 | H20: =E20*0.1 -> 4200 | I20: =E20+F20+G20+H20 -> 58800 | J20: No | K20: M3
A21: IT | B21: Application Developer | C21: 2 | D21: 2000 | E21: =C21*D21*12 -> 48000 | F21: =E21*Assumptions!B37 -> 12000 | G21: =E21*0.05 -> 2400 | H21: 0 | I21: =E21+F21+G21+H21 -> 62400 | J21: No | K21: M4
B22: Subtotal | C22: =SUM(C20:C21) -> 3 | I22: =SUM(I20:I21) -> 121200
A23: MARKETING TEAM (under CMO)
A24: Mktg | B24: Digital Marketing Specialist | C24: 1 | D24: 2000 | E24: =C24*D24*12 -> 24000 | F24: =E24*Assumptions!B37 -> 6000 | G24: =E24*0.05 -> 1200 | H24: 0 | I24: =E24+F24+G24+H24 -> 31200 | J24: No | K24: M5
A25: Mktg | B25: Content / Community Manager | C25: 1 | D25: 1500 | E25: =C25*D25*12 -> 18000 | F25: =E25*Assumptions!B37 -> 4500 | G25: =E25*0.05 -> 900 | H25: 0 | I25: =E25+F25+G25+H25 -> 23400 | J25: No | K25: M6
B26: Subtotal | C26: =SUM(C24:C25) -> 2 | I26: =SUM(I24:I25) -> 54600
A27: SALES (under CCO)
A28: Sales | B28: B2B Sales Industry / Energy | C28: 1 | D28: 2000 | E28: =C28*D28*12 -> 24000 | F28: =E28*Assumptions!B37 -> 6000 | G28: =E28*0.05 -> 1200 | H28: =E28*0.5 -> 12000 | I28: =E28+F28+G28+H28 -> 43200 | J28: No | K28: M8 | L28: https://www.linkedin.com/in/etienne-titi-bakadisansa-62136340/
A29: Sales | B29: B2B Sales BTP | C29: 1 | D29: 2000 | E29: =C29*D29*12 -> 24000 | F29: =E29*Assumptions!B37 -> 6000 | G29: =E29*0.05 -> 1200 | H29: =E29*0.5 -> 12000 | I29: =E29+F29+G29+H29 -> 43200 | J29: No | K29: M8 | L29: https://www.linkedin.com/in/augustin-mbongu-1a3384235/
A30: Sales | B30: B2B Sales Distribution / Resellers | C30: 1 | D30: 2000 | E30: =C30*D30*12 -> 24000 | F30: =E30*Assumptions!B37 -> 6000 | G30: =E30*0.05 -> 1200 | H30: =E30*0.5 -> 12000 | I30: =E30+F30+G30+H30 -> 43200 | J30: No | K30: M8 | L30: https://www.linkedin.com/in/choudhary-muhammad-aamir-saeed-8b45a250/
A31: Sales | B31: Multipurpose land / key accounts | C31: 1 | D31: 1800 | E31: =C31*D31*12 -> 21600 | F31: =E31*Assumptions!B37 -> 5400 | G31: =E31*0.05 -> 1080 | H31: =E31*0.5 -> 10800 | I31: =E31+F31+G31+H31 -> 38880 | J31: No | K31: M8 | L31: https://www.linkedin.com/in/sarahmukonga91/
B32: Subtotal | C32: =SUM(C28:C31) -> 4 | I32: =SUM(I28:I31) -> 168480
A33: OPERATIONS
A34: Ops | B34: Production Operators | C34: 25 | D34: 600 | E34: =C34*D34*12 -> 180000 | F34: =E34*Assumptions!B37 -> 45000 | G34: =E34*0.05 -> 9000 | H34: 0 | I34: =E34+F34+G34+H34 -> 234000 | J34: No | K34: M6-M8
A35: Ops | B35: Truck Drivers | C35: 5 | D35: 1500 | E35: =C35*D35*12 -> 90000 | F35: =E35*Assumptions!B37 -> 22500 | G35: =E35*0.05 -> 4500 | H35: 0 | I35: =E35+F35+G35+H35 -> 117000 | J35: No | K35: M2-M6
A36: Ops | B36: Team Supervisors | C36: 3 | D36: 1200 | E36: =C36*D36*12 -> 43200 | F36: =E36*Assumptions!B37 -> 10800 | G36: =E36*0.05 -> 2160 | H36: 0 | I36: =E36+F36+G36+H36 -> 56160 | J36: No | K36: M6
A37: Ops | B37: Electrician/Technician | C37: 1 | D37: 1500 | E37: =C37*D37*12 -> 18000 | F37: =E37*Assumptions!B37 -> 4500 | G37: =E37*0.05 -> 900 | H37: 0 | I37: =E37+F37+G37+H37 -> 23400 | J37: No | K37: M6
A38: Ops | B38: Warehouse/Logistics | C38: 3 | D38: 800 | E38: =C38*D38*12 -> 28800 | F38: =E38*Assumptions!B37 -> 7200 | G38: =E38*0.05 -> 1440 | H38: 0 | I38: =E38+F38+G38+H38 -> 37440 | J38: No | K38: M3
A39: Ops | B39: Security Guards | C39: 4 | D39: 500 | E39: =C39*D39*12 -> 24000 | F39: =E39*Assumptions!B37 -> 6000 | G39: =E39*0.05 -> 1200 | H39: 0 | I39: =E39+F39+G39+H39 -> 31200 | J39: No | K39: M1
A40: Ops | B40: Cleaning Staff | C40: 2 | D40: 400 | E40: =C40*D40*12 -> 9600 | F40: =E40*Assumptions!B37 -> 2400 | G40: =E40*0.05 -> 480 | H40: 0 | I40: =E40+F40+G40+H40 -> 12480 | J40: No | K40: M3
...

Sheet OPEX_Operations
A1: Cat. | B1: Line Item | C1: Basis | D1: Yr1 ($) | E1: Yr2 ($) | F1: Yr3 ($) | G1: Yr4 ($) | H1: Yr5 ($) | I1: Notes
A2: HUMAN RESOURCES
A3: HR | B3: Internal Payroll (see OPEX_HR) | C3: Progressive hiring | D3: =OPEX_HR!I47*0.55 -> 1280598 | E3: =OPEX_HR!I47*0.85 -> 1979106 | F3: =OPEX_HR!I47*1 -> 2328360 | G3: =OPEX_HR!I47*1 -> 2328360 | H3: =OPEX_HR!I47*1 -> 2328360
B4: Subtotal HR | D4: =D3 -> 1280598 | E4: =E3 -> 1979106 | F4: =F3 -> 2328360 | G4: =G3 -> 2328360 | H4: =H3 -> 2328360
A5: RAW MATERIALS & CONSUMABLES
A6: Materials | B6: Plastic (all sources incl. collectors) | C6: 18,250t×$30/t×ramp | D6: =Assumptions!B10*Assumptions!B30 -> 82125 | E6: =Assumptions!B10*Assumptions!B31 -> 432525 | F6: =Assumptions!B10*Assumptions!B32 -> 531075 | G6: =Assumptions!B10*Assumptions!B33 -> 547500 | H6: =Assumptions!B10*Assumptions!B34 -> 547500
A7: Materials | B7: Water | C7: 200m³/d×$2/m³×365d | D7: =Assumptions!B20*Assumptions!B30 -> 21900 | E7: =Assumptions!B20*Assumptions!B31 -> 115340 | F7: =Assumptions!B20*Assumptions!B32 -> 141620 | G7: =Assumptions!B20*Assumptions!B33 -> 146000 | H7: =Assumptions!B20*Assumptions!B34 -> 146000
A8: Materials | B8: Consumables | C8: Estimate | D8: 24000 | E8: 36000 | F8: 48000 | G8: 48000 | H8: 48000
A9: Materials | B9: Cement BTP | C9: ~3t/d × $100/t × 365d | D9: 44000 | E9: 77000 | F9: 109500 | G9: 109500 | H9: 109500
A10: Materials | B10: Bitumen | C10: Heated mixer | D10: 18000 | E10: 27000 | F10: 36000 | G10: 36000 | H10: 36000
B11: Subtotal Materials | D11: =SUM(D6:D10) -> 190025 | E11: =SUM(E6:E10) -> 687865 | F11: =SUM(F6:F10) -> 866195 | G11: =SUM(G6:G10) -> 887000 | H11: =SUM(H6:H10) -> 887000
A12: ELECTRICITY
A13: Electricity | B13: SNEL+diesel | C13: 115,000kWh/mo blended rate | D13: =Assumptions!B16*Assumptions!B30 -> 47817 | E13: =Assumptions!B16*Assumptions!B31 -> 251836.2 | F13: =Assumptions!B16*Assumptions!B32 -> 309216.6 | G13: =Assumptions!B16*Assumptions!B33 -> 318780 | H13: =Assumptions!B16*Assumptions!B34 -> 318780
B14: Subtotal Electricity | D14: =D13 -> 47817 | E14: =E13 -> 251836.2 | F14: =F13 -> 309216.6 | G14: =G13 -> 318780 | H14: =H13 -> 318780
A15: TRANSPORT & LOGISTICS
A16: Transport | B16: Truck fuel (5 compactors) | D16: =Assumptions!B27*Assumptions!B30 -> 2340 | E16: =Assumptions!B27*Assumptions!B31 -> 12324 | F16: =Assumptions!B27*Assumptions!B32 -> 15132 | G16: =Assumptions!B27*Assumptions!B33 -> 15600 | H16: =Assumptions!B27*Assumptions!B34 -> 15600
A17: Transport | B17: Vehicle fuel | D17: =Assumptions!B28*Assumptions!B30 -> 3159 | E17: =Assumptions!B28*Assumptions!B31 -> 16637.4 | F17: =Assumptions!B28*Assumptions!B32 -> 20428.2 | G17: =Assumptions!B28*Assumptions!B33 -> 21060 | H17: =Assumptions!B28*Assumptions!B34 -> 21060
A18: Transport | B18: Truck maint. | D18: 27000 | E18: 33000 | F18: 36000 | G18: 36000 | H18: 36000
A19: Transport | B19: Vehicle maint. | D19: 13500 | E19: 16500 | F19: 18000 | G19: 18000 | H19: 18000
A20: Transport | B20: Insurance 14 veh. | D20: 14000 | E20: 14000 | F20: 14000 | G20: 14000 | H20: 14000
A21: Transport | B21: Haulage→plant | D21: 30000 | E21: 45000 | F21: 60000 | G21: 60000 | H21: 60000
A22: Transport | B22: Tolls & misc | D22: 4500 | E22: 5500 | F22: 6000 | G22: 6000 | H22: 6000
A23: Transport | B23: Customs & port handling (minor imports) | D23: 5000 | E23: 5000 | F23: 5000 | G23: 5000 | H23: 5000
B24: Subtotal Transport | D24: =SUM(D16:D23) -> 99499 | E24: =SUM(E16:E23) -> 147961.4 | F24: =SUM(F16:F23) -> 174560.2 | G24: =SUM(G16:G23) -> 175660 | H24: =SUM(H16:H23) -> 175660
A25: MAINTENANCE
A26: Maint. | B26: Preventive — machines | D26: 36000 | E26: 44000 | F26: 48000 | G26: 48000 | H26: 48000
A27: Maint. | B27: Preventive — Corrective | D27: 20000 | E27: 25000 | F27: 27000 | G27: 27000 | H27: 27000
A28: Maint. | B28: Maint. Spare parts major | D28: 10000 | E28: 15000 | F28: 20000 | G28: 20000 | H28: 20000
A29: Maint. | B29: Generators | D29: 12000 | E29: 12000 | F29: 12000 | G29: 12000 | H29: 12000
A30: Maint. | B30: Buildings/infra | D30: 9000 | E30: 11000 | F30: 12000 | G30: 12000 | H30: 12000
B31: Subtotal Maint | D31: =SUM(D26:D30) -> 87000 | E31: =SUM(E26:E30) -> 107000 | F31: =SUM(F26:F30) -> 119000 | G31: =SUM(G26:G30) -> 119000 | H31: =SUM(H26:H30) -> 119000
A32: LAND CHARGES
A33: Land | B33: Property taxes | D33: 6000 | E33: 6000 | F33: 6000 | G33: 6000 | H33: 6000
A34: Land | B34: Grounds maint. | D34: 6000 | E34: 6000 | F34: 6000 | G34: 6000 | H34: 6000
B35: Subtotal Land | D35: =SUM(D33:D34) -> 12000 | E35: =SUM(E33:E34) -> 12000 | F35: =SUM(F33:F34) -> 12000 | G35: =SUM(G33:G34) -> 12000 | H35: =SUM(H33:H34) -> 12000
A36: MARKETING & SALES
A37: Mktg | B37: Digital marketing | D37: 18000 | E37: 22000 | F37: 24000 | G37: 24000 | H37: 24000
A38: Mktg | B38: Events/shows/advertising | D38: 12000 | E38: 18000 | F38: 24000 | G38: 24000 | H38: 24000
A39: Mktg | B39: Market penetration/facilitation | D39: 24000 | E39: 30000 | F39: 36000 | G39: 36000 | H39: 36000
A40: Mktg | B40: Samples & demos | D40: 3000 | E40: 4500 | F40: 6000 | G40: 6000 | H40: 6000
...

Sheet Energy_Water_Fuel
A1: Cat. | B1: Item | C1: Spec | D1: Unit kW | E1: Daily kWh | F1: Monthly kWh | G1: Annual kWh | H1: $/kWh | I1: Annual $ | J1: Notes
A2: ELECTRICITY DETAIL
A3: Flux 1 | B3: NIR sorter | C3: 1×5kW | D3: 5 | E3: =1*5*17 -> 85 | F3: =E3*30 -> 2550 | G3: =F3*12 -> 30600 | J3: 17h/day operation
A4: Flux 1 | B4: Washers ×3 | C4: 3×22kW | D4: 22 | E4: =3*22*17 -> 1122 | F4: =E4*30 -> 33660 | G4: =F4*12 -> 403920
A5: Flux 1 | B5: Shredders ×4 | C5: 4×30kW | D5: 30 | E5: =4*30*17 -> 2040 | F5: =E5*30 -> 61200 | G5: =F5*12 -> 734400
A6: Flux 1 | B6: Dryers ×5 | C6: 5×15kW | D6: 15 | E6: =5*15*17 -> 1275 | F6: =E6*30 -> 38250 | G6: =F6*12 -> 459000
A7: Flux 1 | B7: Extruders ×5 | C7: 5×55kW | D7: 55 | E7: =5*55*17 -> 4675 | F7: =E7*30 -> 140250 | G7: =F7*12 -> 1683000 | J7: Main power consumer
A8: Flux 1 | B8: Coolers ×5 | C8: 5×7kW | D8: 7 | E8: =5*7*17 -> 595 | F8: =E8*30 -> 17850 | G8: =F8*12 -> 214200
A9: Flux 1 | B9: Water filt. | C9: 1×3kW | D9: 3 | E9: =1*3*17 -> 51 | F9: =E9*30 -> 1530 | G9: =F9*12 -> 18360
A10: Flux 2 | B10: Fine shredder | C10: 1×22kW | D10: 22 | E10: =1*22*17 -> 374 | F10: =E10*30 -> 11220 | G10: =F10*12 -> 134640
A11: Flux 2 | B11: Rotary dryer | C11: 1×18kW | D11: 18 | E11: =1*18*17 -> 306 | F11: =E11*30 -> 9180 | G11: =F11*12 -> 110160
A12: Flux 2 | B12: Gasifiers ×2 | C12: 2×15kW | D12: 15 | E12: =2*15*17 -> 510 | F12: =E12*30 -> 15300 | G12: =F12*12 -> 183600 | J12: Low elec — thermal process
A13: Flux 2 | B13: Gas filt. | C13: 1×5kW | D13: 5 | E13: =1*5*17 -> 85 | F13: =E13*30 -> 2550 | G13: =F13*12 -> 30600
A14: Flux 2 | B14: LPG comp. ×2 | C14: 2×22kW | D14: 22 | E14: =2*22*17 -> 748 | F14: =E14*30 -> 22440 | G14: =F14*12 -> 269280
A15: Flux 3 | B15: Heavy shredder | C15: 1×30kW | D15: 30 | E15: =1*30*17 -> 510 | F15: =E15*30 -> 15300 | G15: =F15*12 -> 183600
A16: Flux 3 | B16: Bitumen mixer | C16: 1×22kW | D16: 22 | E16: =1*22*17 -> 374 | F16: =E16*30 -> 11220 | G16: =F16*12 -> 134640
A17: Flux 3 | B17: Presses ×3 | C17: 3×37kW | D17: 37 | E17: =3*37*17 -> 1887 | F17: =E17*30 -> 56610 | G17: =F17*12 -> 679320
A18: Shared | B18: Crane | C18: 1×15kW | D18: 15 | E18: =1*15*8 -> 120 | F18: =E18*30 -> 3600 | G18: =F18*12 -> 43200 | J18: 8h/day avg
A19: Shared | B19: Air comp. | C19: 1×7kW | D19: 7 | E19: =1*7*17 -> 119 | F19: =E19*30 -> 3570 | G19: =F19*12 -> 42840
A20: Shared | B20: Light+HVAC | C20: 1×30kW | D20: 30 | E20: =1*30*24 -> 720 | F20: =E20*30 -> 21600 | G20: =F20*12 -> 259200 | J20: 24h (security lighting)
A21: Shared | B21: Pumps ×25 | C21: 25×0.75kW | D21: 0.75 | E21: =25*0.75*17 -> 318.75 | F21: =E21*30 -> 9562.5 | G21: =F21*12 -> 114750 | J21: 17h/day
B22: TOTAL PLANT kWh | E22: =SUM(E3:E21) -> 15914.75 | F22: =SUM(F3:F21) -> 477442.5 | G22: =SUM(G3:G21) -> 5729310
B23: Blended $/kWh | H23: =Assumptions!B14*Assumptions!B13+(1-Assumptions!B13)*Assumptions!B15 -> 0.231 | J23: SNEL 70%+diesel 30%
B24: ANNUAL ELECTRICITY COST | I24: =G22*H23 -> 1323470.6
B25: Cross-check: Assumptions tab | I25: =Assumptions!B16 -> 318780 | J25: Must match Assumptions!B16
A27: WATERCONSUMPTION — see CAPEX_Infra for pump detail
B28: Annual water cost (from Assumptions) | I28: =Assumptions!B20 -> 146000
A29: Flux 1 | B29: Plastic washing | C29: 3 washers | D29: ~50 m³/d total | E29: 50 | F29: =E29*30 -> 1500 | G29: =F29*12 -> 18000
A30: Flux 1 | B30: Rinsing / cooling | C30: Extruders+coolers | D30: ~30 m³/d | E30: 30 | F30: =E30*30 -> 900 | G30: =F30*12 -> 10800
A31: Flux 3 | B31: Bitumen mixer cooling | D31: ~10 m³/d | E31: 10 | F31: =E31*30 -> 300 | G31: =F31*12 -> 3600
A32: Shared | B32: Sanitary / cleaning | C32: ~100 staff | D32: ~20 m³/d | E32: 20 | F32: =E32*30 -> 600 | G32: =F32*12 -> 7200
A33: Shared | B33: Fire reserve / losses | D33: ~10 m³/d | E33: 10 | F33: =E33*30 -> 300 | G33: =F33*12 -> 3600
A34: Shared | B34: Safety margin +20% | C34: Buffer | D34: ~24 m³/d | E34: 24 | F34: =E34*30 -> 720 | G34: =F34*12 -> 8640
B35: TOTAL WATER (m³) | E35: =SUM(E29:E34) -> 144 | F35: =SUM(F29:F34) -> 4320 | G35: =SUM(G29:G34) -> 51840
B36: Cost per m³ | H36: =Assumptions!B19 -> 2
B37: ANNUAL WATER COST (100%) | I37: =G35*H36 -> 103680
A39: FUEL — see Assumptions for vehicle counts
B40: Annual truck fuel | I40: =Assumptions!B27 -> 15600
B41: Annual vehicle fuel | I41: =Assumptions!B28 -> 21060
A43: Trucks | B43: Compactor trucks (10t) | C43: 5 units | D43: 200 L/mo each | E43: 5 | F43: 200 | G43: =E43*F43*12 -> 12000 | H43: =Assumptions!B26 -> 1.3 | I43: =G43*H43 -> 15600 | J43: Collection routes Kinshasa
...

Sheet Working_Capital
A1: MONTHLY BASELINES (at 100% capacity)
A2: Monthly OPEX at 100% | B2: =OPEX_Operations!F53/12 -> 337210.98
A3: Monthly core revenue at 100% | B3: =(Assumptions!B40+Assumptions!B41+Assumptions!B42)/12 -> 1000000
A4: OPEX floor (setup months @ 0% capacity) | B4: 0.14 | C4: 14% = minimum cost ratio during setup (HR+admin before production)
A6: Month | B6: Phase | C6: Cap% | D6: OPEX ($) | E6: Revenue ($) | F6: Net ($) | G6: Cumulative ($) | H6: Milestone
A7: M1 | B7: SETUP | C7: 0 | D7: =$B$2*MAX(C7,$B$4) -> 47209.538 | E7: =$B$3*C7 -> 0 | F7: =E7-D7 -> -47209.538 | G7: =F7 -> -47209.538 | H7: Company registration, exec team hired
A8: M2 | B8: SETUP | C8: 0 | D8: =$B$2*MAX(C8,$B$4) -> 47209.538 | E8: =$B$3*C8 -> 0 | F8: =E8-D8 -> -47209.538 | G8: =G7+F8 -> -94419.075 | H8: 1st truck, collection pilot launch
A9: M3 | B9: COLLECT | C9: 0.05 | D9: =$B$2*MAX(C9,$B$4) -> 47209.538 | E9: =$B$3*C9 -> 50000 | F9: =E9-D9 -> 2790.4623 | G9: =G8+F9 -> -91628.613 | H9: 10-15t/d, raw resale
A10: M4 | B10: COLLECT | C10: 0.08 | D10: =$B$2*MAX(C10,$B$4) -> 47209.538 | E10: =$B$3*C10 -> 80000 | F10: =E10-D10 -> 32790.462 | G10: =G9+F10 -> -58838.151 | H10: 20t/d, land closing
A11: M5 | B11: COLLECT | C11: 0.1 | D11: =$B$2*MAX(C11,$B$4) -> 47209.538 | E11: =$B$3*C11 -> 100000 | F11: =E11-D11 -> 52790.462 | G11: =G10+F11 -> -6047.6883 | H11: 25t/d, construction starts
A12: M6 | B12: COLLECT | C12: 0.12 | D12: =$B$2*MAX(C12,$B$4) -> 47209.538 | E12: =$B$3*C12 -> 120000 | F12: =E12-D12 -> 72790.462 | G12: =G11+F12 -> 66742.774 | H12: 4 trucks ordered, container en route
A13: M7 | B13: INSTALL | C13: 0.12 | D13: =$B$2*MAX(C13,$B$4) -> 47209.538 | E13: =$B$3*C13 -> 120000 | F13: =E13-D13 -> 72790.462 | G13: =G12+F13 -> 139533.24 | H13: Container arrives, installation 17d
A14: M8 | B14: 3 FLUX | C14: 0.15 | D14: =$B$2*MAX(C14,$B$4) -> 50581.647 | E14: =$B$3*C14 -> 150000 | F14: =E14-D14 -> 99418.353 | G14: =G13+F14 -> 238951.59 | H14: ★ 3 FLUX OPERATIONAL
A15: M9 | B15: 3 FLUX | C15: 0.25 | D15: =$B$2*MAX(C15,$B$4) -> 84302.746 | E15: =$B$3*C15 -> 250000 | F15: =E15-D15 -> 165697.25 | G15: =G14+F15 -> 404648.84 | H15: Ramp 25%
A16: M10 | B16: 3 FLUX | C16: 0.35 | D16: =$B$2*MAX(C16,$B$4) -> 118023.84 | E16: =$B$3*C16 -> 350000 | F16: =E16-D16 -> 231976.16 | G16: =G15+F16 -> 636625 | H16: 35%, CFO joins
A17: M11 | B17: 3 FLUX | C17: 0.42 | D17: =$B$2*MAX(C17,$B$4) -> 141628.61 | E17: =$B$3*C17 -> 420000 | F17: =E17-D17 -> 278371.39 | G17: =G16+F17 -> 914996.39 | H17: 42%
A18: M12 | B18: 3 FLUX | C18: 0.48 | D18: =$B$2*MAX(C18,$B$4) -> 161861.27 | E18: =$B$3*C18 -> 480000 | F18: =E18-D18 -> 318138.73 | G18: =G17+F18 -> 1233135.1 | H18: ★ MONTHLY EBITDA POSITIVE
A19: M13 | B19: RAMP | C19: 0.52 | D19: =$B$2*MAX(C19,$B$4) -> 175349.71 | E19: =$B$3*C19 -> 520000 | F19: =E19-D19 -> 344650.29 | G19: =G18+F19 -> 1577785.4 | H19: 52%, CCO operational
... A30: M24 | B30: CRUISE | C30: 0.95 | D30: =$B$2*MAX(C30,$B$4) -> 320350.43 | E30: =$B$3*C30 -> 950000 | F30: =E30-D30 -> 629649.57 | G30: =G29+F30 -> 6986143.8 | H30: ★ 95% nominal reached
A32: WORKING CAPITAL ANALYSIS (all formulas — fully dynamic) | J32: Project Profile | K32: Typical Safety Factor | L32: Exemple
B33: Peak negative cash | G33: =MIN(G7:G30) -> -94419.075 | J33: Tech SaaS | K33: 3-5x | L33: Predictable cashflow
B34: Safety Factor | G34: =K36 -> 25 | H34: Covers worst-case cash shortfall for DRC operational risks | J34: Industrial France | K34: 8-12x | L34: Controlled logistics
B35: Budgeted WC | G35: =ABS(G33)*G34 -> 2360476.9 | J35: Emerging Africa | K35: 15-25x | L35: Opportunity/currency risks
B36: Safety margin | G36: =G35-ABS(G33) -> 2266057.8 | H36: WC minus |Peak| | J36: TakaPlast choice | K36: 25 | L36: Pyrolysis + energy
B37: Safety margin % | G37: =IF(G33=0,0,G35/ABS(G33)-1) -> 24 | H37: Target: >100% above peak
B39: NOTE: All values in this tab are formula-driven. Change Assumptions (ramp rates, prices, consumption) or OPEX_Operations and this tab updates automatically. From M12: EBITDA positive monthly. Plant self-financing from Year 2.

Sheet Revenue
A1: Flux | B1: Product | C1: Vol Yr3 | D1: Price | E1: Yr1 ($) | F1: Yr2 ($) | G1: Yr3 ($) | H1: Yr4 ($) | I1: Yr5 ($) | J1: Margin | K1: Notes
A2: CORE REVENUE (at 100% = Assumptions B40-B42, scaled by ramp B30-B34)
A3: Pellets | B3: HDPE/PP Pellets | C3: 11,077t/yr | D3: $650/t | E3: =Assumptions!B40*Assumptions!B30 -> 1080000 | F3: =Assumptions!B40*Assumptions!B31 -> 5688000 | G3: =Assumptions!B40*Assumptions!B32 -> 6984000 | H3: =Assumptions!B40*Assumptions!B33 -> 7200000 | I3: =Assumptions!B40*Assumptions!B34 -> 7200000 | J3: 0.48 | K3: Based on Assumptions ramp rate
A4: BTP | B4: Plastic-cement pavers | C4: 276,000m²/yr | D4: $10/m² | E4: =Assumptions!B41*Assumptions!B30 -> 414000 | F4: =Assumptions!B41*Assumptions!B31 -> 2180400 | G4: =Assumptions!B41*Assumptions!B32 -> 2677200 | H4: =Assumptions!B41*Assumptions!B33 -> 2760000 | I4: =Assumptions!B41*Assumptions!B34 -> 2760000 | J4: 0.45 | K4: Based on Assumptions ramp rate
A5: Energy | B5: LPG / Syngas | C5: 2.4M L/yr | D5: $0.85/L | E5: =Assumptions!B42*Assumptions!B30 -> 306000 | F5: =Assumptions!B42*Assumptions!B31 -> 1611600 | G5: =Assumptions!B42*Assumptions!B32 -> 1978800 | H5: =Assumptions!B42*Assumptions!B33 -> 2040000 | I5: =Assumptions!B42*Assumptions!B34 -> 2040000 | J5: 0.52 | K5: Based on Assumptions ramp rate
B6: Subtotal Core | E6: =SUM(E3:E5) -> 1800000 | F6: =SUM(F3:F5) -> 9480000 | G6: =SUM(G3:G5) -> 11640000 | H6: =SUM(H3:H5) -> 12000000 | I6: =SUM(I3:I5) -> 12000000
A8: COMPLEMENTARY REVENUE (probability-weighted, NOT in base payback)
B9: Carbon credits (Gold Standard) | C9: 15K→55K tCO2eq scaling | E9: 0 | F9: 0 | G9: =Assumptions!B44 -> 420750 | H9: =Assumptions!B45 -> 981750 | I9: =Assumptions!B46 -> 1544994 | J9: 86 | K9: Yr3: 15K tCO2 (conservative). Yr4: 35K. Yr5: 55,080 (full 50t/d impact = 55K tCO2eq/yr)
B10: Tipping fees | C10: ~5,000t×$50/t | E10: 0 | F10: =Assumptions!B47*Assumptions!B31 -> 197500 | G10: =Assumptions!B47*Assumptions!B32 -> 242500 | H10: =Assumptions!B47 -> 250000 | I10: =Assumptions!B47 -> 250000 | J10: 45 | K10: Bralima, EGMF — starts M14
B11: Export pellets (Congo-Brazza) | C11: 750t×$800/t FOB | E11: 0 | F11: 0 | G11: 0 | H11: =Assumptions!B48 -> 600000 | I11: =Assumptions!B48 -> 600000 | J11: 38 | K11: ISO 9001 prerequisite
B12: Training + Consulting | C12: Academy 120 tech + AMO | E12: 0 | F12: 0 | G12: 0 | H12: =Assumptions!B50 -> 200000 | I12: =Assumptions!B50 -> 200000 | J12: 65 | K12: INPP partnership
B13: Franchise intra-Congo | C13: $25K + 5% CA royalties | E13: 0 | F13: 0 | G13: 0 | H13: 0 | I13: =Assumptions!B49 -> 750000 | J13: 75 | K13: Requires 2-year track record
B14: Subtotal Complementary | E14: =SUM(E9:E13) -> 0 | F14: =SUM(F9:F13) -> 197500 | G14: =SUM(G9:G13) -> 663250 | H14: =SUM(H9:H13) -> 2031750 | I14: =SUM(I9:I13) -> 3344994
B16: TOTAL REVENUE (core + complementary) | E16: =E6+E14 -> 1800000 | F16: =F6+F14 -> 9677500 | G16: =G6+G14 -> 12303250 | H16: =H6+H14 -> 14031750 | I16: =I6+I14 -> 15344994
A18: SIMPLIFIED P&L (5-year view)
B19: Revenue (core only) | E19: =E6 -> 1800000 | F19: =F6 -> 9480000 | G19: =G6 -> 11640000 | H19: =H6 -> 12000000 | I19: =I6 -> 12000000
B20: Total OPEX | E20: =OPEX_Operations!D53 -> 1837139 | F20: =OPEX_Operations!E53 -> 3365468.6 | G20: =OPEX_Operations!F53 -> 4046531.8 | H20: =OPEX_Operations!G53 -> 4098000 | I20: =OPEX_Operations!H53 -> 4118000
B21: EBITDA (core) | E21: =E19-E20 -> -37139 | F21: =F19-F20 -> 6114531.4 | G21: =G19-G20 -> 7593468.2 | H21: =H19-H20 -> 7902000 | I21: =I19-I20 -> 7882000
B22: EBITDA margin % | E22: =IF(E19=0,0,E21/E19) -> -0.020632778 | F22: =IF(F19=0,0,F21/F19) -> 0.64499276 | G22: =IF(G19=0,0,G21/G19) -> 0.65235981 | H22: =IF(H19=0,0,H21/H19) -> 0.6585 | I22: =IF(I19=0,0,I21/I19) -> 0.65683333

Sheet Subsidies
A1: Org | B1: Program | C1: Max ($) | D1: Criteria | E1: Prob. | F1: Window | G1: Time | H1: Status
A2: INTERNATIONAL
A3: AfDB | B3: Circular economy | C3: 600000 | D3: Clean tech, EIA | E3: 60% | F3: M6-M12 | G3: 12-18mo | H3: To file
A4: UNDP | B4: Waste Kinshasa | C4: 250000 | D4: SDG 11-13 | E4: 70% | F4: M4-M10 | G4: 6-12mo | H4: Priority
A5: AFD | B5: Priv. sector innov. | C5: 500000 | D5: Sustainable dev | E5: 55% | F5: M8-M14 | G5: 12-18mo | H5: To file
A6: EU | B6: Green Deal C.Africa | C6: 150000 | D6: Pilot grant | E6: 40% | F6: M12-M24 | G6: 12-18mo | H6: To file
A7: GCF | B7: Climate adapt. | C7: 500000 | D7: Via ministry | E7: 35% | F7: M6-M18 | G7: 18-24mo | H7: Long-term
A8: Gates | B8: Urban Health | C8: 500000 | D8: Waste-health | E8: 25% | F8: M12-M24 | G8: 18-24mo | H8: Exploratory
A9: WB/IFC | B9: Green SME | C9: 300000 | D9: Green Economy | E9: 40% | F9: M8-M18 | G9: 12-18mo | H9: Explore
B10: Subtotal Intl | C10: 2800000
A11: FRENCH
A12: BPI | B12: Innovation/export | C12: 500000 | D12: FR entity | E12: 45% | F12: M6-M12 | G12: 6-9mo | H12: To file
A13: ADEME | B13: Intl circular econ. | C13: 200000 | D13: Recycling, CO2 | E13: 40% | F13: M8-M14 | G13: 9-12mo | H13: To file
A14: FASEP | B14: Feasibility | C14: 300000 | D14: Demonstrator | E14: 50% | F14: M4-M10 | G14: 6-12mo | H14: To file
A15: Proparco | B15: Priv.sector | C15: 1000000 | D15: Co-investment | E15: 35% | F15: M10-M18 | G15: 12-18mo | H15: Explore
B16: Subtotal French | C16: 2000000
A17: CONGOLESE
A18: CPS (Crédit Pays Solution) | B18: National program | C18: 200000 | D18: Industrial dev. | E18: 45% | F18: M4-M10 | G18: 6-12mo | H18: Research
A19: FPI | B19: SME support | C19: 100000 | D19: Local Industry | E19: 50% | F19: M4-M8 | G19: 3-6mo | H19: To file
A20: Kinshasa prov. | B20: Sanitation | C20: 50000 | D20: Waste, youth | E20: 45% | F20: M3-M8 | G20: 3-6mo | H20: To file
B21: Subtotal Congolese | C21: 350000
B23: TOTAL POTENTIAL SUBSIDIES | C23: =C10+C16+C21 -> 5150000
B25: NOTE: Subsidies NOT included in payback/ROI. If awarded = upside for investors.
